2023-02-02 14:56:50,987 INFO    MainThread:3692 [internal.py:wandb_internal():89] W&B internal server running at pid: 3692, started at: 2023-02-02 14:56:50.986188
2023-02-02 14:56:50,993 DEBUG   HandlerThread:3692 [handler.py:handle_request():131] handle_request: check_version
2023-02-02 14:56:50,994 INFO    WriterThread:3692 [datastore.py:open_for_write():77] open: /data/tproth/travis_release/wandb/run-20230202_145647-dtzshych/run-dtzshych.wandb
2023-02-02 14:56:50,996 DEBUG   SenderThread:3692 [sender.py:send():235] send: header
2023-02-02 14:56:50,996 DEBUG   SenderThread:3692 [sender.py:send_request():249] send_request: check_version
2023-02-02 14:56:51,049 DEBUG   SenderThread:3692 [sender.py:send():235] send: run
2023-02-02 14:56:51,323 ERROR   SenderThread:3692 [internal_api.py:execute():143] 404 response executing GraphQL.
2023-02-02 14:56:51,323 ERROR   SenderThread:3692 [internal_api.py:execute():144] {"errors":[{"message":"entity entity_name not found during upsertBucket","path":["upsertBucket"]}],"data":{"upsertBucket":null}}
2023-02-02 14:56:52,049 INFO    WriterThread:3692 [datastore.py:close():281] close: /data/tproth/travis_release/wandb/run-20230202_145647-dtzshych/run-dtzshych.wandb
2023-02-02 14:56:52,049 INFO    HandlerThread:3692 [handler.py:finish():739] shutting down handler
2023-02-02 14:56:52,051 ERROR   MainThread:3692 [internal.py:wandb_internal():164] Thread SenderThread:
Traceback (most recent call last):
  File "/home/tproth/Programs/miniconda/envs/constrained_adversarial_reward/lib/python3.10/site-packages/wandb/sdk/lib/retry.py", line 102, in __call__
    result = self._call_fn(*args, **kwargs)
  File "/home/tproth/Programs/miniconda/envs/constrained_adversarial_reward/lib/python3.10/site-packages/wandb/sdk/internal/internal_api.py", line 146, in execute
    six.reraise(*sys.exc_info())
  File "/home/tproth/Programs/miniconda/envs/constrained_adversarial_reward/lib/python3.10/site-packages/six.py", line 719, in reraise
    raise value
  File "/home/tproth/Programs/miniconda/envs/constrained_adversarial_reward/lib/python3.10/site-packages/wandb/sdk/internal/internal_api.py", line 140, in execute
    return self.client.execute(*args, **kwargs)
  File "/home/tproth/Programs/miniconda/envs/constrained_adversarial_reward/lib/python3.10/site-packages/wandb/vendor/gql-0.2.0/gql/client.py", line 52, in execute
    result = self._get_result(document, *args, **kwargs)
  File "/home/tproth/Programs/miniconda/envs/constrained_adversarial_reward/lib/python3.10/site-packages/wandb/vendor/gql-0.2.0/gql/client.py", line 60, in _get_result
    return self.transport.execute(document, *args, **kwargs)
  File "/home/tproth/Programs/miniconda/envs/constrained_adversarial_reward/lib/python3.10/site-packages/wandb/vendor/gql-0.2.0/gql/transport/requests.py", line 39, in execute
    request.raise_for_status()
  File "/home/tproth/Programs/miniconda/envs/constrained_adversarial_reward/lib/python3.10/site-packages/requests/models.py", line 1021, in raise_for_status
    raise HTTPError(http_error_msg, response=self)
requests.exceptions.HTTPError: 404 Client Error: Not Found for url: https://api.wandb.ai/graphql

During handling of the above exception, another exception occurred:

Traceback (most recent call last):
  File "/home/tproth/Programs/miniconda/envs/constrained_adversarial_reward/lib/python3.10/site-packages/wandb/apis/normalize.py", line 24, in wrapper
    return func(*args, **kwargs)
  File "/home/tproth/Programs/miniconda/envs/constrained_adversarial_reward/lib/python3.10/site-packages/wandb/sdk/internal/internal_api.py", line 1296, in upsert_run
    response = self.gql(mutation, variable_values=variable_values, **kwargs)
  File "/home/tproth/Programs/miniconda/envs/constrained_adversarial_reward/lib/python3.10/site-packages/wandb/sdk/lib/retry.py", line 118, in __call__
    if not check_retry_fn(e):
  File "/home/tproth/Programs/miniconda/envs/constrained_adversarial_reward/lib/python3.10/site-packages/wandb/util.py", line 821, in no_retry_auth
    raise CommError("Permission denied, ask the project owner to grant you access")
wandb.errors.CommError: Permission denied, ask the project owner to grant you access

During handling of the above exception, another exception occurred:

Traceback (most recent call last):
  File "/home/tproth/Programs/miniconda/envs/constrained_adversarial_reward/lib/python3.10/site-packages/wandb/sdk/internal/internal_util.py", line 54, in run
    self._run()
  File "/home/tproth/Programs/miniconda/envs/constrained_adversarial_reward/lib/python3.10/site-packages/wandb/sdk/internal/internal_util.py", line 105, in _run
    self._process(record)
  File "/home/tproth/Programs/miniconda/envs/constrained_adversarial_reward/lib/python3.10/site-packages/wandb/sdk/internal/internal.py", line 305, in _process
    self._sm.send(record)
  File "/home/tproth/Programs/miniconda/envs/constrained_adversarial_reward/lib/python3.10/site-packages/wandb/sdk/internal/sender.py", line 237, in send
    send_handler(record)
  File "/home/tproth/Programs/miniconda/envs/constrained_adversarial_reward/lib/python3.10/site-packages/wandb/sdk/internal/sender.py", line 692, in send_run
    self._init_run(run, config_value_dict)
  File "/home/tproth/Programs/miniconda/envs/constrained_adversarial_reward/lib/python3.10/site-packages/wandb/sdk/internal/sender.py", line 716, in _init_run
    server_run, inserted = self._api.upsert_run(
  File "/home/tproth/Programs/miniconda/envs/constrained_adversarial_reward/lib/python3.10/site-packages/wandb/apis/normalize.py", line 62, in wrapper
    six.reraise(CommError, CommError(message, err), sys.exc_info()[2])
  File "/home/tproth/Programs/miniconda/envs/constrained_adversarial_reward/lib/python3.10/site-packages/six.py", line 718, in reraise
    raise value.with_traceback(tb)
  File "/home/tproth/Programs/miniconda/envs/constrained_adversarial_reward/lib/python3.10/site-packages/wandb/apis/normalize.py", line 24, in wrapper
    return func(*args, **kwargs)
  File "/home/tproth/Programs/miniconda/envs/constrained_adversarial_reward/lib/python3.10/site-packages/wandb/sdk/internal/internal_api.py", line 1296, in upsert_run
    response = self.gql(mutation, variable_values=variable_values, **kwargs)
  File "/home/tproth/Programs/miniconda/envs/constrained_adversarial_reward/lib/python3.10/site-packages/wandb/sdk/lib/retry.py", line 118, in __call__
    if not check_retry_fn(e):
  File "/home/tproth/Programs/miniconda/envs/constrained_adversarial_reward/lib/python3.10/site-packages/wandb/util.py", line 821, in no_retry_auth
    raise CommError("Permission denied, ask the project owner to grant you access")
wandb.errors.CommError: Permission denied, ask the project owner to grant you access
2023-02-02 14:56:54,730 INFO    MainThread:3692 [internal.py:handle_exit():79] Internal process exited
